<?xml version="1.0"?>
<robot xmlns:xacro="http://www.ros.org/wiki/xacro" name="robot_name">

    <xacro:property name="PI" value="3.14159" />
    <xacro:property name="effort" value="30.0" />
    <xacro:property name="velocity" value="10.0" />
    <xacro:property name="stl_path" value="package://arduino_bot_desc/meshes/" />


    <link name="world"/>

    <link name="base_link">
        <visual>
            <origin xyz="-0.5 -0.5 0" rpy="0 0 0"/>
            <geometry>
                <mesh filename="${stl_path}basement.STL" scale="0.01 0.01 0.01"/>
            </geometry>
        </visual>
    </link>
    <joint name="my_virtual_joint" type="fixed">
        <origin xyz="0.0 0.0 0.0" rpy="0.0 0.0 0.0"/>
        <parent link="world"/>
        <child link="base_link"/>
    </joint>

    <link name="base_plate">
        <visual>
            <origin xyz="-0.39 -0.39 -0.56" rpy="0.0 0.0 0.0"/>
            <geometry>
                <mesh filename="${stl_path}base_plate.STL" scale="0.01 0.01 0.01"/>
            </geometry>
        </visual>
    </link>
    <joint name="joint_1" type="revolute">
        <origin xyz="0 0 0.307" rpy="0.0 0.0 0.0"/>
        <parent link="base_link"/>
        <child link="base_plate"/>
        <axis xyz="0 0 1"/>
        <limit lower="-${PI/2}" upper="${PI/2}" effort="${effort}" velocity="${velocity}"/>
    </joint>


    <link name="forward_drive_arm">
        <visual>
            <origin xyz="0.19 0.06 -0.08" rpy="0.0 -${PI/2} ${PI/2}"/>
            <geometry>
                <mesh filename="${stl_path}forward_drive_arm.STL" scale="0.01 0.01 0.01"/>
            </geometry>
        </visual>
    </link>
    <joint name="joint_2" type="revolute">
        <origin xyz="-0.02 0 0.35" rpy="0.0 0.0 0.0"/>
        <parent link="base_plate"/>
        <child link="forward_drive_arm"/>
        <axis xyz="1 0 0"/>
        <limit lower="-${PI/2}" upper="${PI/2}" effort="${effort}" velocity="${velocity}"/>
    </joint>


    <link name="horizontal_arm">
        <visual>
            <origin xyz="-0.03 -0.4 -0.06" rpy="${PI/2} 0 ${PI/2}"/>
            <geometry>
                <mesh filename="${stl_path}horizontal_arm.STL" scale="0.01 0.01 0.01"/>
            </geometry>
        </visual>
    </link>
    <joint name="joint_3" type="revolute">
        <origin xyz="0 0 0.8" rpy="0.0 0.0 0.0"/>
        <parent link="forward_drive_arm"/>
        <child link="horizontal_arm"/>
        <axis xyz="1 0 0"/>
        <limit lower="-${PI/2}" upper="${PI/2}" effort="${effort}" velocity="${velocity}"/>
    </joint>

    <link name="claw_support">
        <visual>
            <origin xyz="0 -0.05 -0.15" rpy="0 0 ${PI/2}"/>
            <geometry>
                <mesh filename="${stl_path}claw_support.STL" scale="0.01 0.01 0.01"/>
            </geometry>
        </visual>
    </link>
    <joint name="horizontal_arm_to_claw_support" type="fixed">
        <origin xyz="0 0.82 0" rpy="0.0 0.0 0.0"/>
        <parent link="horizontal_arm"/>
        <child link="claw_support"/>
    </joint>

    <link name="gripper_right">
        <visual>
            <origin xyz="-0.1 0.5 -0.1" rpy="0 0 -${PI/2}"/>
            <geometry>
                <mesh filename="${stl_path}right_finger.STL" scale="0.01 0.01 0.01"/>
            </geometry>
        </visual>
    </link>
    <link name="gripper_left">
        <visual>
            <origin xyz="-0.04 0.5 -0.1" rpy="0 0 -${PI/2}"/>
            <geometry>
                <mesh filename="${stl_path}left_finger.STL" scale="0.01 0.01 0.01"/>
            </geometry>
        </visual>
    </link>
    <joint name="joint_4" type="revolute">
        <origin xyz="-0.04 0.13 -0.1" rpy="0.0 0.0 0.0"/>
        <parent link="claw_support"/>
        <child link="gripper_right"/>
        <axis xyz="0 0 1"/>
        <limit lower="-${PI/2}" upper="0.0" effort="${effort}" velocity="${velocity}"/>
    </joint>
    <joint name="joint_5" type="revolute">
        <origin xyz="-0.22 0.13 -0.1" rpy="0.0 0.0 0.0"/>
        <parent link="claw_support"/>
        <child link="gripper_left"/>
        <axis xyz="0 0 1"/>
        <limit lower="0.0" upper="${PI/2}" effort="${effort}" velocity="${velocity}"/>
        <mimic joint="joint_4" multiplier="-1"/>
    </joint>

</robot>
